Workbook

Sheet 汇总
A1: 表1 XX项目初步设计投资估算汇总表
A2: 序 号 | B2: 项 目 | C2: 金额（人民币元） | D2: 备注
A3: 一 | B3: 硬件设备购置费 | C3: =硬件设备购置费!G30 -> 0
A4: 二 | B4: 定制软件开发费 | C4: ='定制软件开发费（功能点法）'!D26 -> 297669.27 | E4: 当前使用功能点预估表费用，包含（EIF、ILF）
A5: 三 | B5: 系统集成实施费与其他费 | C5: =系统集成实施费与其他费!G33 -> 17860.156
A6: 四 | B6: 项目建设其他费 | C6: =项目建设其他费!D11 -> 0
A7: 五 | B7: 合计 | C7: =SUM(C3:C6) -> 315529.43
A9: 表1 XX项目初步设计投资估算汇总表
A10: 序 号 | B10: 项 目 | C10: 金额（人民币元） | D10: 备注
A11: 一 | B11: 硬件设备购置费 | C11: =硬件设备购置费!G30 -> 0
A12: 二 | B12: 定制软件开发费 | C12: ='定制软件开发费（功能点法） (估算）'!D26 -> 75209.259 | E12: 当前使用功能点估算表费用（包括ILF/EIF/EI/EO/EQ）
A13: 三 | B13: 系统集成实施费与其他费 | C13: =系统集成实施费与其他费!G33 -> 17860.156
A14: 四 | B14: 项目建设其他费 | C14: =项目建设其他费!D11 -> 0
A15: 五 | B15: 合计 | C15: =SUM(C11:C14) -> 93069.416
A17: 注：1.声明：初始各表所列的示例数据是模拟计算的数据，目的是为了方便使用表格关联性和计算公式，没有项目真实金额的意义； 2.表中的一、二、三、四、五项对应金额无需填写，由“硬件设备购置费”“定制软件开发费”“系统集成实施费与其他费”“项目建设其他费”四个子表的各项相关数据自动关联生成。 3. 根据不同的阶段选择不同的表模板使用，原则上功能点识别只需要填写《定制软件开发功能点明细表（预估）》， 定制软件开发费根据其填写内容自动生成。 此表为示范例子，项目的整体投资应严格按照海南省政务信息化系统项目支出测算标准及评审指南（试行）要求进行取数和测算，特别是需要充分做好市场调查，设备、成品软件、数据资源、数据服务等购买根据额度要求，应提供三个或以上同级别不同品牌厂商（代理商）的询价报价单。如硬件询价报价单应包括品牌名称、设备型号及功能性能参数、单价、报价单位名称（加盖公章）、联系人及电话等内容，或提供近六个月内政府采购项目中同类型同级别设备的中标（合同）价格及相关有效证明材料。

Sheet 硬件设备购置费
A1: 表2 硬件设备及材料购置投资估算表
A2: 序号 | B2: 名 称 | C2: 技术参数与参考品牌 | D2: 单位 | E2: 数量 | F2: 单价（元） | G2: 金额（元） | H2: 备注 (价格市场调研依据说明等)
A3: 一 | B3: XXX系统
A4: 1.1 | B4: 硬件 | G4: =E4*F4 -> 0
A5: 1 | B5: 服务器 | D5: 台 | E5: 0 | F5: 56000 | G5: =F5*E5 -> 0
A6: 2 | B6: 存储 | D6: 套 | E6: 0 | F6: 780000 | G6: =F6*E6 -> 0
A7: 3 | B7: 备份 | D7: 套 | E7: 0 | F7: 100000 | G7: =F7*E7 -> 0
A8: 4 | B8: 网络 | F8: …
A9: 5 | B9: 安全 | F9: …
A10: … | F10: …
A11: 1.2 | B11: 材料
A12: 1 | B12: 材料1 | D12: 件 | E12: 0 | F12: 20000 | G12: =F12*E12 -> 0
A13: 2 | B13: … | F13: …
A14: 3 | B14: … | F14: …
A15: … | B15: … | F15: …
A16: i | B16: … | F16: …
B17: 小计1 | F17: =SUM(F4:F16) -> 956000 | G17: =SUM(G4:G16) -> 0
A18: 二 | B18: XXX系统
A19: i
A20: …
B30: 合计 | G30: =G29+G22+G17 -> 0 | H30: 各小计项之和
A32: 注：1.表中的“单价”系模拟数字，仅供关联计算，没有实际价格意义。请在实际使用此表时，根据当时、当地的取费依据据实填写。原则上，软硬件设备单价10000元以上或单一类型软硬件设备总价40000元以上的，需提供三个或以上同级别不同品牌厂商（代理商）的询价报价单。询价报价单应包括品牌名称、规格型号及功能性能参数、单价、报价单位名称（加盖公章）、联系人及电话等内容，或提供近六个月内政府采购项目中同类型同级别设备的中标（合同）价格及相关有效证明材料。 2.已对此子表的各数据项设置了与其他子表和汇总表的计算关联，使用时仅需根据项目的实际情况填入具体数字即可。

Sheet 定制软件开发功能点明细表(预估）
A1: 表4 功能点明细表
A2: 编号 | B2: 功能模块 | C2: 功能子模块 | D2: 功能点计数项名称 | E2: 类别 | F2: UFP （未经调整的功能点） | G2: 重用程度 | H2: US (调整的功能点） | I2: 备注
A3: 1 | B3: 新业务系统1 | C3: 日程安排 | D3: 日程安排 | E3: ILF | F3: =IF("ILF"=E3,35, IF("EIF"=E3, 15,0) ) -> 35 | G3: 中 | H3: =ROUND(IF(G3="高",1/3,IF(G3="中",2/3,1)) *F3,2) -> 23.33
A4: 2 | D4: 提醒 | E4: ILF | F4: =IF("ILF"=E4,35, IF("EIF"=E4, 15,0) ) -> 35 | G4: 高 | H4: =ROUND(IF(G4="高",1/3,IF(G4="中",2/3,1)) *F4,2) -> 11.67
A5: 3 | D5: 信息 | E5: EIF | F5: =IF("ILF"=E5,35, IF("EIF"=E5, 15,0) ) -> 15 | G5: 低 | H5: =ROUND(IF(G5="高",1/3,IF(G5="中",2/3,1)) *F5,2) -> 15
A6: 4 | D6: 用户 | E6: EIF | F6: =IF("ILF"=E6,35, IF("EIF"=E6, 15,0) ) -> 15 | G6: 中 | H6: =ROUND(IF(G6="高",1/3,IF(G6="中",2/3,1)) *F6,2) -> 10
A7: 5 | D7: xxx | F7: =IF("ILF"=E7,35, IF("EIF"=E7, 15,0) ) -> 0 | H7: =ROUND(IF(G7="高",1/3,IF(G7="中",2/3,1)) *F7,2) -> 0
A8: ... | B8: 新业务系统2 | C8: 业务领域专栏 | D8: 专栏与子栏目 | E8: ILF | F8: =IF("ILF"=E8,35, IF("EIF"=E8, 15,0) ) -> 35 | G8: 中 | H8: =ROUND(IF(G8="高",1/3,IF(G8="中",2/3,1)) *F8,2) -> 23.33
D9: 业务专题 | E9: ILF | F9: =IF("ILF"=E9,35, IF("EIF"=E9, 15,0) ) -> 35 | G9: 中 | H9: =ROUND(IF(G9="高",1/3,IF(G9="中",2/3,1)) *F9,2) -> 23.33
D10: 部门 | E10: EIF | F10: =IF("ILF"=E10,35, IF("EIF"=E10, 15,0) ) -> 15 | G10: 中 | H10: =ROUND(IF(G10="高",1/3,IF(G10="中",2/3,1)) *F10,2) -> 10
C11: 模块3 | D11: xxx | E11: ILF | F11: =IF("ILF"=E11,35, IF("EIF"=E11, 15,0) ) -> 35 | G11: 中 | H11: =ROUND(IF(G11="高",1/3,IF(G11="中",2/3,1)) *F11,2) -> 23.33
D12: ... | F12: =IF("ILF"=E12,35, IF("EIF"=E12, 15,0) ) -> 0 | G12: 中 | H12: =ROUND(IF(G12="高",1/3,IF(G12="中",2/3,1)) *F12,2) -> 0
C13: 模块4 | D13: xxx | E13: ILF | F13: =IF("ILF"=E13,35, IF("EIF"=E13, 15,0) ) -> 35 | G13: 中 | H13: =ROUND(IF(G13="高",1/3,IF(G13="中",2/3,1)) *F13,2) -> 23.33
D14: ... | F14: =IF("ILF"=E14,35, IF("EIF"=E14, 15,0) ) -> 0 | G14: 中 | H14: =ROUND(IF(G14="高",1/3,IF(G14="中",2/3,1)) *F14,2) -> 0
C15: 模块5 | D15: xxx | E15: ILF | F15: =IF("ILF"=E15,35, IF("EIF"=E15, 15,0) ) -> 35 | G15: 中 | H15: =ROUND(IF(G15="高",1/3,IF(G15="中",2/3,1)) *F15,2) -> 23.33
D16: ... | F16: =IF("ILF"=E16,35, IF("EIF"=E16, 15,0) ) -> 0 | G16: 中 | H16: =ROUND(IF(G16="高",1/3,IF(G16="中",2/3,1)) *F16,2) -> 0
C17: 事务功能模块6 | D17: xxx | E17: EIF | F17: =IF("ILF"=E17,35, IF("EIF"=E17, 15,0) ) -> 15 | G17: 中 | H17: =ROUND(IF(G17="高",1/3,IF(G17="中",2/3,1)) *F17,2) -> 10
D18: ... | E18: ILF | F18: =IF("ILF"=E18,35, IF("EIF"=E18, 15,0) ) -> 35 | G18: 中 | H18: =ROUND(IF(G18="高",1/3,IF(G18="中",2/3,1)) *F18,2) -> 23.33
A19: ... | B19: ... | C19: 数据功能模块7 | E19: ILF | F19: =IF("ILF"=E19,35, IF("EIF"=E19, 15,0) ) -> 35 | G19: 中 | H19: =ROUND(IF(G19="高",1/3,IF(G19="中",2/3,1)) *F19,2) -> 23.33
A20: 合计 | F20: =SUM(F3:F19) -> 375 | H20: =SUM(H3:H19) -> 243.31
A21: 注：1.此功能点明细表以及合计功能点数仅为示例，无实际意义，请在使用此表时据实识别功能点并填写； 2.在项目建议书及可行性研究报告及估算阶段宜采用预估功能点方法进行功能点规模测算。 初步设计按估算功能点计数法：UFP=10×ILF+7×EIF+4×EI+5×EO+4×EQ

Sheet 定制软件开发费（功能点法）
A1: 表3.1 功能点测算规模、工作量、工期、费用表
A2: 1.未调整功能点数UFP（功能点） | C2: ='定制软件开发功能点明细表(预估）'!F20 -> 375
A3: 经复用调整后的功能点数US（功能点） | C3: ='定制软件开发功能点明细表(预估）'!H20 -> 243.31
A4: 设定规模变更因子CF | B4: 1.39 | D4: 初步设计取值为1.25 在项目建议书及可行性研究报告及估算阶段宜采用预估功能点方法进行功能点规模测算，取1.39 | E4: 根据《2021年中国软件行业基准数据》： 在估算早期（概算、预算阶段），取值1.39; 在估算中期（如投标、项目计划阶段），取值1.21； 在估算晚期（如需求分析阶段），取值1.10
A5: 2.调整后功能点数S（功能点） | B5: S=UFP*CF （无复用度） | C5: =C2*B4 -> 521.25
B6: S=US*CF （调整复用度） | C6: =C3*B4 -> 338.2009
A7: 功能点耗时率（PDR） （人时/功能点） | C7: 下限值（P25） | D7: 3.99
C8: 中间值（P50） | D8: 7.19 | E8: 根据2020年中国软件行业基准数据（CSBMK®-202010）
C9: 上限值（P75） | D9: 12.48
A10: 3.未调整的工作量UE（人时） 计算公式：UE=PDR×S | C10: 下限值（P25） | D10: =D7*C6 -> 1349.4216
C11: 中间值（P50） | D11: =D8*C6 -> 2431.6645
C12: 上限值（P75） | D12: =D9*C6 -> 4220.7472
A13: 设定调整因子 | C13: 应用类型调整因子AT | D13: 1
C14: 质量特性调整因子QR | D14: 1
A15: 4.调整后的工作量AE（人时） 计算公式：AE=UE×SWF; 其中SWF=AT×QR; | C15: 下限值（P25） | D15: =D10*D13*D14 -> 1349.4216
C16: 中间值（P50） | D16: =D11*D13*D14 -> 2431.6645
C17: 上限值（P75） | D17: =D12*D13*D14 -> 4220.7472
A18: 人月折算系数HM（人时/人月） | D18: 174
A19: 平均人力成本费率F（元/人月） | D19: 21300
A20: 5.工期D（月） 计算公式：D=1.277×(AE/8/22)0.404 | C20: 下限值（P25） | D20: =1.277*POWER(D15/8/22,0.404) -> 2.9079265
C21: 中间值（P50） | D21: =1.277*POWER(D16/8/22,0.404) -> 3.6890017
C22: 上限值（P75） | D22: =1.277*POWER(D17/8/22,0.404) -> 4.609577
A23: 6.软件开发费用（元） 计算公式：P=AE/HM×F | C23: 下限值（P25） | D23: =D15/D18*D19 -> 165187.82
C24: 中间值（P50） | D24: =D16/D18*D19 -> 297669.27
C25: 上限值（P75） | D25: =D17/D18*D19 -> 516677.68
C26: 最终费用/价格（元） | D26: =D24 -> 297669.27
A27: 调整后功能点数S单价 | C27: 功能点单价（元/功能点） | D27: =D26/C6 -> 880.15517
A28: 注：1.表中的应用类型调整因子与质量特性调整因子见下表；此表数据仅供计算方法参考，具体数据无实际意义。 2.表中的功能点数系模拟数字，仅供关联计算参考，其数据没有实际价格意义,请在实际使用此表时，据实填写。
A29: 表3.2 定制软件开发应用类型调整因子取值明细表
A30: 应用类型 | B30: 描述 | C30: 调整因子 | D30: 选择 | E30: 备注
A31: 业务处理 | B31: OA、公文，人事、会计、工资等经营管理及业务处理应用软件 | C31: 1 | D31: 1
A32: 科技、应用集成 | B32: 科学计算、模拟、空白表格程序，统计等；服务总线、应用集成等 | C32: 1.2
A33: 多媒体 | B33: 图表，影像，声音等多媒体应用领域，地理信息系统，教育和媒体应用等 | C33: 1.3
A34: 智能信息 | B34: 自然语言处理，人工智能，专家系统等 | C34: 1.7
A35: 系统 | B35: 操作系统，语言处理程序，DBMS，人与机器的接口，窗口系统，CASE，实用程序，自动化开发/设计工具等 | C35: 1.7
A36: 通信控制 | B36: 通信协议，仿真，交换机软件，GPS等 | C36: 1.9
A37: 流程控制 | B37: 仪器控制，机器人控制，实时控制，内置性软件等 | C37: 2
A39: 表3.3 定制软件开发质量特性调整因子取值明细表
A40: 调整因子 | B40: 判断标准 | C40: 调整因子 | D40: 选择 | E40: 备注
A41: 性能效率 | B41: 没有明示对性能效率的需求 | C41: -1 | D41: -1
...

Sheet 定制软件开发功能点明细表(估算）
A1: 表4 功能点明细表
A2: 编号 | B2: 功能模块 | C2: 功能子模块 | D2: 功能点计数项名称 | E2: 类别 | F2: UFP （未经调整的功能点） | G2: 重用程度 | H2: US (调整的功能点） | I2: 备注
A3: 1 | B3: 新业务系统1 | C3: 日程安排 | D3: 日程安排 | E3: ILF | F3: =IF("ILF"=E3,10, IF("EIF"=E3, 7,IF(E3="EI", 4, IF(E3="EO", 5, IF(E3="EQ", 4, 0))) )) -> 10 | G3: 中 | H3: =ROUND(IF(G3="高",1/3,IF(G3="中",2/3,1)) *F3,2) -> 6.67
A4: 2 | D4: 提醒 | E4: ILF | F4: =IF("ILF"=E4,10, IF("EIF"=E4, 7,IF(E4="EI", 4, IF(E4="EO", 5, IF(E4="EQ", 4, 0))) )) -> 10 | G4: 高 | H4: =ROUND(IF(G4="高",1/3,IF(G4="中",2/3,1)) *F4,2) -> 3.33
A5: 3 | D5: 信息 | E5: EIF | F5: =IF("ILF"=E5,10, IF("EIF"=E5, 7,IF(E5="EI", 4, IF(E5="EO", 5, IF(E5="EQ", 4, 0))) )) -> 7 | G5: 低 | H5: =ROUND(IF(G5="高",1/3,IF(G5="中",2/3,1)) *F5,2) -> 7
A6: 4 | D6: 用户 | E6: EIF | F6: =IF("ILF"=E6,10, IF("EIF"=E6, 7,IF(E6="EI", 4, IF(E6="EO", 5, IF(E6="EQ", 4, 0))) )) -> 7 | G6: 中 | H6: =ROUND(IF(G6="高",1/3,IF(G6="中",2/3,1)) *F6,2) -> 4.67
A7: 5 | D7: xxx | F7: =IF("ILF"=E7,10, IF("EIF"=E7, 7,IF(E7="EI", 4, IF(E7="EO", 5, IF(E7="EQ", 4, 0))) )) -> 0 | H7: =ROUND(IF(G7="高",1/3,IF(G7="中",2/3,1)) *F7,2) -> 0
A8: ... | B8: 新业务系统2 | C8: 业务领域专栏 | D8: 专栏与子栏目 | E8: ILF | F8: =IF("ILF"=E8,10, IF("EIF"=E8, 7,IF(E8="EI", 4, IF(E8="EO", 5, IF(E8="EQ", 4, 0))) )) -> 10 | G8: 中 | H8: =ROUND(IF(G8="高",1/3,IF(G8="中",2/3,1)) *F8,2) -> 6.67
D9: 业务专题 | E9: ILF | F9: =IF("ILF"=E9,10, IF("EIF"=E9, 7,IF(E9="EI", 4, IF(E9="EO", 5, IF(E9="EQ", 4, 0))) )) -> 10 | G9: 中 | H9: =ROUND(IF(G9="高",1/3,IF(G9="中",2/3,1)) *F9,2) -> 6.67
D10: 部门 | E10: EIF | F10: =IF("ILF"=E10,10, IF("EIF"=E10, 7,IF(E10="EI", 4, IF(E10="EO", 5, IF(E10="EQ", 4, 0))) )) -> 7 | G10: 中 | H10: =ROUND(IF(G10="高",1/3,IF(G10="中",2/3,1)) *F10,2) -> 4.67
C11: 模块3 | D11: xxx | E11: ILF | F11: =IF("ILF"=E11,10, IF("EIF"=E11, 7,IF(E11="EI", 4, IF(E11="EO", 5, IF(E11="EQ", 4, 0))) )) -> 10 | G11: 中 | H11: =ROUND(IF(G11="高",1/3,IF(G11="中",2/3,1)) *F11,2) -> 6.67
D12: ... | F12: =IF("ILF"=E12,10, IF("EIF"=E12, 7,IF(E12="EI", 4, IF(E12="EO", 5, IF(E12="EQ", 4, 0))) )) -> 0 | G12: 中 | H12: =ROUND(IF(G12="高",1/3,IF(G12="中",2/3,1)) *F12,2) -> 0
C13: 模块4 | D13: xxx | E13: ILF | F13: =IF("ILF"=E13,10, IF("EIF"=E13, 7,IF(E13="EI", 4, IF(E13="EO", 5, IF(E13="EQ", 4, 0))) )) -> 10 | G13: 中 | H13: =ROUND(IF(G13="高",1/3,IF(G13="中",2/3,1)) *F13,2) -> 6.67
D14: ... | F14: =IF("ILF"=E14,10, IF("EIF"=E14, 7,IF(E14="EI", 4, IF(E14="EO", 5, IF(E14="EQ", 4, 0))) )) -> 0 | G14: 中 | H14: =ROUND(IF(G14="高",1/3,IF(G14="中",2/3,1)) *F14,2) -> 0
C15: 模块5 | D15: xxx | E15: EQ | F15: =IF("ILF"=E15,10, IF("EIF"=E15, 7,IF(E15="EI", 4, IF(E15="EO", 5, IF(E15="EQ", 4, 0))) )) -> 4 | G15: 中 | H15: =ROUND(IF(G15="高",1/3,IF(G15="中",2/3,1)) *F15,2) -> 2.67
D16: ... | F16: =IF("ILF"=E16,10, IF("EIF"=E16, 7,IF(E16="EI", 4, IF(E16="EO", 5, IF(E16="EQ", 4, 0))) )) -> 0 | G16: 中 | H16: =ROUND(IF(G16="高",1/3,IF(G16="中",2/3,1)) *F16,2) -> 0
C17: 事务功能模块6 | D17: xxx | E17: EI | F17: =IF("ILF"=E17,10, IF("EIF"=E17, 7,IF(E17="EI", 4, IF(E17="EO", 5, IF(E17="EQ", 4, 0))) )) -> 4 | G17: 中 | H17: =ROUND(IF(G17="高",1/3,IF(G17="中",2/3,1)) *F17,2) -> 2.67
D18: ... | E18: EO | F18: =IF("ILF"=E18,10, IF("EIF"=E18, 7,IF(E18="EI", 4, IF(E18="EO", 5, IF(E18="EQ", 4, 0))) )) -> 5 | G18: 中 | H18: =ROUND(IF(G18="高",1/3,IF(G18="中",2/3,1)) *F18,2) -> 3.33
A19: ... | B19: ... | C19: 数据功能模块7 | E19: ILF | F19: =IF("ILF"=E19,10, IF("EIF"=E19, 7,IF(E19="EI", 4, IF(E19="EO", 5, IF(E19="EQ", 4, 0))) )) -> 10 | G19: 中 | H19: =ROUND(IF(G19="高",1/3,IF(G19="中",2/3,1)) *F19,2) -> 6.67
A20: 合计 | F20: =SUM(F3:F19) -> 104 | H20: =SUM(H3:H19) -> 68.36
A21: 注：1.此功能点明细表以及合计功能点数仅为示例，无实际意义，请在使用此表时据实识别功能点并填写； 2.在项目建议书及可行性研究报告及估算阶段宜采用预估功能点方法进行功能点规模测算。 初步设计按估算功能点计数法：UFP=10×ILF+7×EIF+4×EI+5×EO+4×EQ

Sheet 定制软件开发费（功能点法） (估算）
A1: 表3.1 功能点测算规模、工作量、工期、费用表
A2: 1.未调整功能点数UFP（功能点） | C2: ='定制软件开发功能点明细表(估算）'!F20 -> 104
A3: 经复用调整后的功能点数US（功能点） | C3: ='定制软件开发功能点明细表(估算）'!H20 -> 68.36
A4: 设定规模变更因子CF | B4: 1.25 | D4: 初步设计取值为1.25 在项目建议书及可行性研究报告及估算阶段宜采用预估功能点方法进行功能点规模测算，取1.39
A5: 2.调整后功能点数S（功能点） | B5: S=UFP*CF （无复用度） | C5: =C2*B4 -> 130
B6: S=US*CF （调整复用度） | C6: =C3*B4 -> 85.45
A7: 功能点耗时率（PDR） （人时/功能点） | C7: 下限值（P25） | D7: 3.99
C8: 中间值（P50） | D8: 7.19 | E8: 根据2020年中国软件行业基准数据（CSBMK®-202010）
C9: 上限值（P75） | D9: 12.48
A10: 3.未调整的工作量UE（人时） 计算公式：UE=PDR×S | C10: 下限值（P25） | D10: =D7*C6 -> 340.9455
C11: 中间值（P50） | D11: =D8*C6 -> 614.3855
C12: 上限值（P75） | D12: =D9*C6 -> 1066.416
A13: 设定调整因子 | C13: 应用类型调整因子AT | D13: 1
C14: 质量特性调整因子QR | D14: 1
A15: 4.调整后的工作量AE（人时） 计算公式：AE=UE×SWF; 其中SWF=AT×QR; | C15: 下限值（P25） | D15: =D10*D13*D14 -> 340.9455
C16: 中间值（P50） | D16: =D11*D13*D14 -> 614.3855
C17: 上限值（P75） | D17: =D12*D13*D14 -> 1066.416
A18: 人月折算系数HM（人时/人月） | D18: 174
A19: 平均人力成本费率F（元/人月） | D19: 21300
A20: 5.工期D（月） 计算公式：D=1.277×(AE/8/22)0.404 | C20: 下限值（P25） | D20: =1.277*POWER(D15/8/22,0.404) -> 1.6680478
C21: 中间值（P50） | D21: =1.277*POWER(D16/8/22,0.404) -> 2.116089
C22: 上限值（P75） | D22: =1.277*POWER(D17/8/22,0.404) -> 2.6441504
A23: 6.软件开发费用（元） 计算公式：P=AE/HM×F | C23: 下限值（P25） | D23: =D15/D18*D19 -> 41736.432
C24: 中间值（P50） | D24: =D16/D18*D19 -> 75209.259
C25: 上限值（P75） | D25: =D17/D18*D19 -> 130544.03
C26: 最终费用/价格（元） | D26: =D24 -> 75209.259
A27: 调整后功能点数S单价 | C27: 功能点单价（元/功能点） | D27: =D26/C6 -> 880.15517
A28: 注：1.表中的应用类型调整因子与质量特性调整因子见下表；此表数据仅供计算方法参考，具体数据无实际意义。 2.表中的功能点数系模拟数字，仅供关联计算参考，其数据没有实际价格意义,请在实际使用此表时，据实填写。
A29: 表3.2 定制软件开发应用类型调整因子取值明细表
A30: 应用类型 | B30: 描述 | C30: 调整因子 | D30: 选择 | E30: 备注
A31: 业务处理 | B31: OA、公文，人事、会计、工资等经营管理及业务处理应用软件 | C31: 1 | D31: 1
A32: 科技、应用集成 | B32: 科学计算、模拟、空白表格程序，统计等；服务总线、应用集成等 | C32: 1.2
A33: 多媒体 | B33: 图表，影像，声音等多媒体应用领域，地理信息系统，教育和媒体应用等 | C33: 1.3
A34: 智能信息 | B34: 自然语言处理，人工智能，专家系统等 | C34: 1.7
A35: 系统 | B35: 操作系统，语言处理程序，DBMS，人与机器的接口，窗口系统，CASE，实用程序，自动化开发/设计工具等 | C35: 1.7
A36: 通信控制 | B36: 通信协议，仿真，交换机软件，GPS等 | C36: 1.9
A37: 流程控制 | B37: 仪器控制，机器人控制，实时控制，内置性软件等 | C37: 2
A39: 表3.3 定制软件开发质量特性调整因子取值明细表
A40: 调整因子 | B40: 判断标准 | C40: 调整因子 | D40: 选择 | E40: 备注
A41: 性能效率 | B41: 没有明示对性能效率的需求 | C41: -1 | D41: -1
...

Sheet 定制软件开发费（专家经验法）
A1: 表5 软件开发投资估算表
A2: 序号 | B2: 名 称 | C2: 业务系统 | D2: 子系统模块 | E2: 功能描述 | F2: 工作量(人月） | G2: 单价（元/人月） | H2: 金额（元） | I2: 备注
A3: 1 | B3: 用户自行命名 | C3: AAA | D3: aaa | H3: =F3*G3 -> 0
A4: 2 | D4: bbb | H4: =F4*G4 -> 0
A5: 3 | D5: ccc | H5: =F5*G5 -> 0
A6: … | D6: …
A7: i | D7: iii | H7: =F7*G7 -> 0
C8: 小计1 | H8: =SUM(H3:H7) -> 0
A9: 1 | C9: BBB | D9: aaa | H9: =F9*G9 -> 0
A10: 2 | D10: bbb | H10: =F10*G10 -> 0
A11: 3 | D11: ccc | H11: =F11*G11 -> 0
A12: … | D12: …
A13: i | D13: iii | H13: =F13*G13 -> 0
C14: 小计2 | H14: =SUM(H9:H13) -> 0
A15: 1 | C15: CCC | D15: aaa | H15: =F15*G15 -> 0
A16: 2 | D16: bbb | H16: =F16*G16 -> 0
A17: 3 | D17: ccc | H17: =F17*G17 -> 0
A18: … | D18: …
A19: i | D19: iii | H19: =F19*G19 -> 0
C20: 小计3 | H20: =SUM(H15:H19) -> 0
A21: 1 | C21: DDD | D21: aaa | H21: =F21*G21 -> 0
A22: 2 | D22: bbb | H22: =F22*G22 -> 0
A23: 3 | D23: ccc | H23: =F23*G23 -> 0
A24: … | D24: …
A25: i | D25: iii | H25: =F25*G25 -> 0
C26: 小计j | H26: =SUM(H21:H25) -> 0
C27: 合计 | H27: =H8+H14+H20+H26 -> 0 | I27: 各小计项之和
A29: 注：1.专家经验估算软件开发工作量法适用于不能采用估算软件开发工作量法的情形，建设单位须举证说明原因。 2. 采用专家经验法估算工作量时应依据项目建设方案并结合项目实际进行测算。 3.表中的“工作量”和“单价”系模拟数字，仅供参考。请在实际使用此表时，根据当时、当地的取费依据据实填写“工作量”和“单价”即可；

Sheet 系统集成实施费与其他费
A1: 表7 系统集成实施费与其他费用投资估算表
A2: 系统集成实施服务费
A3: 序号 | B3: 名称 | G3: 金额（元） | H3: 备注
B4: 建设费用
A5: 1 | B5: 硬件设备购置费 | G5: =硬件设备购置费!G30 -> 0
A6: 2 | B6: 定制软件开发费 | G6: ='定制软件开发费（功能点法）'!D26 -> 297669.27
B7: 需集成的各项小计 | G7: =SUM(G5:G6) -> 297669.27
B8: 系统集成实施费 | G8: =(G5)*0.04+G6*0.06 -> 17860.156 | H8: 基础环境集成实施费按不高于3%计取；硬件集成实施费按不高于5%计取；软件集成实施费按不高于8%计取。
B9: 其他费用
A10: 序号 | B10: 名称 | C10: 相关指标或用途说明 | D10: 单位 | E10: 数量或工作量（人月） | F10: 单价（元或元/人月） | G10: 金额（元） | H10: 备注
A11: 1 | B11: 标准规范编制费
A12: 1.1 | B12: xxx标准 | E12: 0 | F12: 21300 | G12: =E12*F12 -> 0
A13: 1.2 | B13: xxx标准 | E13: 0 | F13: 21300 | G13: =E13*F13 -> 0
A14: ...
A15: 2 | B15: 与项目建设强相关的安装费
A16: 2.1
A17: 2.2
A18: ...
A19: 3 | B19: 电费
A20: 3.1
A21: 3.2
A22: ...
A23: 4 | B23: 云资源租赁费
A24: 4.1
A25: 4.2
A26: ...
A27: 5 | B27: 网络租赁费
A28: 6 | B28: 系统迁移费
A29: 7 | B29: 应用系统推广培训费
A30: …
A31: i | B31: …
B32: 其他费小计 | G32: =SUM(G11:G31) -> 0
B33: 合计 | G33: =G8+G32 -> 17860.156
A34: 注：1.表中的“金额”系模拟数字，无实际意义，请在实际使用此表时，根据海南省政务信息化系统支出测算标准及评审指南相关费用计取方法计算填写。 2.其他费用中所列费用应根据项目实际需要编列； 3.已对此子表的各数据项设置了与其他子表和汇总表的计算关联，使用时仅需根据项目的实际情况填入具体数字即可。

Sheet 项目建设其他费
A1: 表8 项目建设其他费投资概算表
A2: 序号 | B2: 名称 | C2: 取费标准 | D2: 金额（元） | E2: 备注
A3: 1 | B3: 项目建议书编制费 | C3: 海南省政务信息化系统支出测算标准及评审指南（试行）；参考计价格[1999]1283号 | D3: 0 | E3: 海南省政务信息化系统支出测算标准及评审指南，按难易度据实计取。此项根据实际列支。
A4: 2 | B4: 可行性研究报告编制费 | C4: 海南省政务信息化系统支出测算标准及评审指南（试行） | D4: 0 | E4: 海南省政务信息化系统支出测算标准及评审指南（试行），计费基价按直线内插法计算，专业调整系数采用加权方式计算。此项根据实际列支。
A5: 3 | B5: 初步设计编制费 | C5: 海南省政务信息化系统支出测算标准及评审指南（试行） | D5: 0 | E5: 海南省政务信息化系统支出测算标准及评审指南（试行），计费基价按直线内插法计算，专业调整系数采用加权方式计算。
A6: 4 | B6: 监理服务费 | C6: 海南省政务信息化系统支出测算标准及评审指南（试行） | D6: 0 | E6: 海南省政务信息化系统支出测算标准及评审指南（试行），计费基价按直线内插法计算，专业调整系数采用加权方式计算。
A7: 5 | B7: 软件测评费 | C7: 海南省政务信息化系统支出测算标准及评审指南（试行） | D7: 0 | E7: 海南省政务信息化系统支出测算标准及评审指南（试行），采用差额定率累进法计算。
A8: 6 | B8: 网络安全等级保护测评费（或分级保护测评费） | C8: 海南省政务信息化系统支出测算标准及评审指南（试行）；参考琼国密局字〔2021〕2号、琼财信〔2018〕1357号，等保三级测评费≤8万元，密评费≤12万元；等保二级测评费≤5万元，密评费≤8万元。 | D8: 0 | E8: 1.海南省国家密码局等《关于进一步明确政务信息化项目建设密码应用有关要求的通知》（琼国密局字〔2021〕2号）； 2.海南省政务信息化系统支出测算标准及评审指南（试行）。
A9: 7 | B9: 商用密码应用安全性评估费 | C9: 海南省政务信息化系统支出测算标准及评审指南（试行）；参考琼国密局字〔2021〕2号、琼财信〔2018〕1357号，等保三级测评费≤8万元，密评费≤12万元；等保二级测评费≤5万元，密评费≤8万元。 | D9: 0 | E9: 1.海南省国家密码局等《关于进一步明确政务信息化项目建设密码应用有关要求的通知》（琼国密局字〔2021〕2号）； 2.海南省政务信息化系统支出测算标准及评审指南（试行）。
A10: 8 | B10: ...
B11: 小计3 | D11: =SUM(D3:D9) -> 0
A13: 注：1.表中的“金额”系模拟数字，无实际意义，请在实际使用此表时，根据海南省政务信息化系统支出测算标准及评审指南相关费用计取方法计算填写。 2.已对此子表的各数据项设置了与其他子表和汇总表的计算关联，使用时仅需根据项目的实际情况填入具体数字即可； 3.因工程实际需要、项目所在地区相关标准和行业规范要求必须计列的其他费用，可选列，但须提供投资估算计列标准和依据。
